Workbook
Name anaaa: 'Tabela Dinamica1'!$B$16
Name biiiii: 'Tabela Dinamica1'!$I$16
Name cieenn: 'Tabela Dinamica1'!$F$16
Name ciencia: 'Tabela Dinamica1'!$F$5
Name Excel: 'Tabela Dinamica1'!$I$4
Name SegmentaçãodeDados_Mês: #N/A
Name Total_1: 'Tabela Dinamica1'!$B$5

Sheet Base
A7: ID | B7: Data | C7: Mês | D7: Nome | E7: Email | F7: Telefone | G7: Produto | H7: Valor_Produto | I7: Quantidade Vendida | J7: Região | K7: Status | L7: Motivo | M7: Comissão
A8: 1 | B8: 45646 | C8: =UPPER(TEXT(Dados_Cursos[[#This Row],[Data]],"mmm")) -> DEZ | D8: Bruno Barbosa | E8: =VLOOKUP(Dados_Cursos[[#This Row],[ID]],Apoio!A1:H1001,2,0) -> bruno.barbosa1@gmail.com | F8: (16) 9 8428-9249 | G8: Curso Excel & Power BI | H8: 1200 | I8: 6 | J8: =VLOOKUP(Dados_Cursos[[#This Row],[ID]],Apoio!A1:H1001,4,0) -> Bié | K8: Venda Realizada | L8: Aprovado
A9: 2 | B9: 45586 | C9: =UPPER(TEXT(Dados_Cursos[[#This Row],[Data]],"mmm")) -> OUT | D9: Paulo Pinto | E9: =VLOOKUP(Dados_Cursos[[#This Row],[ID]],Apoio!A2:H1002,2,0) -> paulo.pinto2@gmail.com | F9: (55) 9 9961-7341 | G9: Ciência de Dados | H9: 1500 | I9: 2 | J9: =VLOOKUP(Dados_Cursos[[#This Row],[ID]],Apoio!A2:H1002,4,0) -> Huíla | K9: Venda Realizada | L9: Aprovado
A10: 3 | B10: 45390 | C10: =UPPER(TEXT(Dados_Cursos[[#This Row],[Data]],"mmm")) -> ABR | D10: Fátima Fernandes | E10: =VLOOKUP(Dados_Cursos[[#This Row],[ID]],Apoio!A3:H1003,2,0) -> fátima.fernandes3@gmail.com | F10: (49) 9 9756-7039 | G10: Curso Excel & Power BI | H10: 1200 | I10: 13 | J10: =VLOOKUP(Dados_Cursos[[#This Row],[ID]],Apoio!A3:H1003,4,0) -> Icolo e Bengo | K10: Venda Perdida | L10: Nº Incorreto Cartão
A11: 4 | B11: 45490 | C11: =UPPER(TEXT(Dados_Cursos[[#This Row],[Data]],"mmm")) -> JUL | D11: Samuel Monteiro | E11: =VLOOKUP(Dados_Cursos[[#This Row],[ID]],Apoio!A4:H1004,2,0) -> samuel.monteiro4@gmail.com | F11: (59) 9 8661-9214 | G11: Ciência de Dados | H11: 800 | I11: 16 | J11: =VLOOKUP(Dados_Cursos[[#This Row],[ID]],Apoio!A4:H1004,4,0) -> Malanje | K11: Venda Perdida | L11: Abandono Carrinho
A12: 5 | B12: 45539 | C12: =UPPER(TEXT(Dados_Cursos[[#This Row],[Data]],"mmm")) -> SET | D12: Joaquim Lopes | E12: =VLOOKUP(Dados_Cursos[[#This Row],[ID]],Apoio!A5:H1005,2,0) -> joaquim.lopes5@gmail.com | F12: (59) 9 7601-7334 | G12: Curso Excel & Power BI | H12: 1200 | I12: 11 | J12: =VLOOKUP(Dados_Cursos[[#This Row],[ID]],Apoio!A5:H1005,4,0) -> Namibe | K12: Venda Perdida | L12: Abandono Carrinho
A13: 6 | B13: 45482 | C13: =UPPER(TEXT(Dados_Cursos[[#This Row],[Data]],"mmm")) -> JUL | D13: Manuel Almeida | E13: =VLOOKUP(Dados_Cursos[[#This Row],[ID]],Apoio!A6:H1006,2,0) -> manuel.almeida6@gmail.com | F13: (52) 9 8931-9507 | G13: Curso Excel & Power BI | H13: 1200 | I13: 13 | J13: =VLOOKUP(Dados_Cursos[[#This Row],[ID]],Apoio!A6:H1006,4,0) -> Lunda Sul | K13: Venda Perdida | L13: Nº Incorreto Cartão
A14: 7 | B14: 45518 | C14: =UPPER(TEXT(Dados_Cursos[[#This Row],[Data]],"mmm")) -> AGO | D14: Samuel David | E14: =VLOOKUP(Dados_Cursos[[#This Row],[ID]],Apoio!A7:H1007,2,0) -> samuel.david7@gmail.com | F14: (37) 9 8647-7509 | G14: Ciência de Dados | H14: 1500 | I14: 17 | J14: =VLOOKUP(Dados_Cursos[[#This Row],[ID]],Apoio!A7:H1007,4,0) -> Moxico Leste | K14: Venda Perdida | L14: Nº Incorreto Cartão
A15: 8 | B15: 45403 | C15: =UPPER(TEXT(Dados_Cursos[[#This Row],[Data]],"mmm")) -> ABR | D15: António Gomes | E15: =VLOOKUP(Dados_Cursos[[#This Row],[ID]],Apoio!A8:H1008,2,0) -> antónio.gomes8@gmail.com | F15: (48) 9 9757-7386 | G15: Curso Excel & Power BI | H15: 1200 | I15: 5 | J15: =VLOOKUP(Dados_Cursos[[#This Row],[ID]],Apoio!A8:H1008,4,0) -> Uíge | K15: Venda Perdida | L15: Nº Incorreto Cartão
A16: 9 | B16: 45322 | C16: =UPPER(TEXT(Dados_Cursos[[#This Row],[Data]],"mmm")) -> JAN | D16: António Fernandes | E16: =VLOOKUP(Dados_Cursos[[#This Row],[ID]],Apoio!A9:H1009,2,0) -> antónio.fernandes9@gmail.com | F16: (11) 9 8709-8767 | G16: Ciência de Dados | H16: 800 | I16: 8 | J16: =VLOOKUP(Dados_Cursos[[#This Row],[ID]],Apoio!A9:H1009,4,0) -> Moxico | K16: Venda Realizada | L16: Aprovado
A17: 10 | B17: 45547 | C17: =UPPER(TEXT(Dados_Cursos[[#This Row],[Data]],"mmm")) -> SET | D17: Benedito Barbosa | E17: =VLOOKUP(Dados_Cursos[[#This Row],[ID]],Apoio!A10:H1010,2,0) -> benedito.barbosa10@gmail.com | F17: (58) 9 7037-8428 | G17: Ciência de Dados | H17: 800 | I17: 13 | J17: =VLOOKUP(Dados_Cursos[[#This Row],[ID]],Apoio!A10:H1010,4,0) -> Icolo e Bengo | K17: Venda Perdida | L17: Nº Incorreto Cartão
A18: 11 | B18: 45506 | C18: =UPPER(TEXT(Dados_Cursos[[#This Row],[Data]],"mmm")) -> AGO | D18: Carlos Lukeba | E18: =VLOOKUP(Dados_Cursos[[#This Row],[ID]],Apoio!A11:H1011,2,0) -> carlos.lukeba11@gmail.com | F18: (15) 9 7414-9114 | G18: Ciência de Dados | H18: 1500 | I18: 13 | J18: =VLOOKUP(Dados_Cursos[[#This Row],[ID]],Apoio!A11:H1011,4,0) -> Benguela | K18: Venda Realizada | L18: Aprovado
A19: 12 | B19: 45399 | C19: =UPPER(TEXT(Dados_Cursos[[#This Row],[Data]],"mmm")) -> ABR | D19: David Santos | E19: =VLOOKUP(Dados_Cursos[[#This Row],[ID]],Apoio!A12:H1012,2,0) -> david.santos12@gmail.com | F19: (55) 9 8691-7285 | G19: Ciência de Dados | H19: 800 | I19: 14 | J19: =VLOOKUP(Dados_Cursos[[#This Row],[ID]],Apoio!A12:H1012,4,0) -> Lunda Sul | K19: Venda Perdida | L19: Abandono Carrinho
... A1007: 1000 | B1007: 45535 | C1007: =UPPER(TEXT(Dados_Cursos[[#This Row],[Data]],"mmm")) -> AGO | D1007: Samuel David | E1007: =VLOOKUP(Dados_Cursos[[#This Row],[ID]],Apoio!A1000:H2000,2,0) -> samuel.david1000@gmail.com | F1007: (17) 9 7622-8305 | G1007: Ciência de Dados | H1007: 800 | I1007: 5 | J1007: =VLOOKUP(Dados_Cursos[[#This Row],[ID]],Apoio!A1000:H2000,4,0) -> Uíge | K1007: Venda Perdida | L1007: Nº Incorreto Cartão
E1009: =COUNTA(E8:E1007) -> 1000

Sheet Relatório
W1: CONTA , CONTA.SE, SOMA, SOMSAS, PROCV, SE, E OU , DIVIDE
A2: RELATÓRIO POR PRODUTO
A3: Produto | D3: Quantidade | G3: Valor Pago | J3: % Vendas | M3: Comissão | P3: Bonus
A4: Curso Excel & Power BI | D4: =COUNTIF(Base!G:G,Relatório!A4) -> 136 | G4: =SUMIF(Base!G:G,Relatório!A4,Base!H:H) -> 163200 | J4: =G4/G7 -> 0.13848112 | M4: =IF(AND(D4>=$D$14,$G$4>=D13),8%*D4,0) -> 0 | P4: =IF(OR(D4>=D14,G4>=D13),5%*G4,"Sem comissão") -> 8160
A5: Análise de Dados | D5: =COUNTIF(Base!G:G,Relatório!A5) -> 227 | G5: =SUMIF(Base!G:G,Relatório!A5,Base!H:H) -> 340500 | J5: =G5/G7 -> 0.2889266 | M5: =IF(AND(D5>=$D$14,$G$4>=D14),8%*D5,0) -> 18.16 | P5: =IF(OR(D5>=D15,G5>=D14),5%*G5,"Sem comissão") -> 17025
A6: Ciência de Dados | D6: =COUNTIF(Base!G:G,Relatório!A6) -> 637 | G6: =SUMIF(Base!G:G,Relatório!A6,Base!H:H) -> 674800 | J6: =G6/G7 -> 0.57259228 | M6: =IF(AND(D6>=$D$14,$G$4>=D15),8%*D6,0) -> 50.96 | P6: =IF(OR(D6>=D16,G6>=D15),5%*G6,"Sem comissão") -> 33740
A7: Total | D7: =SUM(D4:F6) -> 1000 | G7: =SUM(G4:I6) -> 1178500 | J7: =SUM(J4:L6) -> 1 | M7: =SUM(M4:O6) -> 69.12 | P7: =SUM(P4:R6) -> 58925
A12: META | D12: VALOR
A13: Valor Pago | D13: 10000
A14: Quantidade | D14: 200
A30: RELATÓRIO POR STATUS
A34: RELATÓRIO POR STATUS
A35: Status | D35: Quantidade | G35: Valor Pago | J35: % Vendas | M35: Comissão
A36: Venda Realizada | D36: =COUNTIF(Base!K8:K1007,Relatório!A36) -> 264 | G36: =SUMIF(Base!K8:K1007,Relatório!A36,Base!H8:H1007) -> 306900 | J36: =G36/G38 -> 0.26041578
A37: Venda Perdida | D37: =COUNTIF(Base!K9:K1008,Relatório!A37) -> 736 | G37: =SUMIF(Base!K9:K1008,Relatório!A37,Base!H9:H1008) -> 871600 | J37: =G37/G38 -> 0.73958422
A38: Total | D38: =SUM(D36,D37) -> 1000 | G38: =SUM(G36,G37) -> 1178500 | J38: =SUM(J36,J37) -> 1
C54: RELATÓRIO POR MOTIVOS
C55: MOTIVO | F55: Quantidade | I55: Valor Pago | L55: % Vendas | O55: Comissão
C56: Aprovado | F56: =COUNTIF(Base!L8:L1007,Relatório!C56) -> 264 | I56: =SUMIF(Base!L8:L1007,Relatório!C56,Base!H8:H1007) -> 306900 | L56: =I56/I60 -> 0.26041578
C57: Nº Incorreto Cartão | F57: =COUNTIF(Base!L9:L1008,Relatório!C57) -> 244 | I57: =SUMIF(Base!L9:L1008,Relatório!C57,Base!H9:H1008) -> 289600 | L57: =I57/I60 -> 0.24573611
C58: Abandono Carrinho | F58: =COUNTIF(Base!L10:L1009,Relatório!C58) -> 245 | I58: =SUMIF(Base!L10:L1009,Relatório!C58,Base!H10:H1009) -> 294200 | L58: =I58/I60 -> 0.24963937
C59: Saldo Insuficiente | F59: =COUNTIF(Base!L11:L1010,Relatório!C59) -> 247 | I59: =SUMIF(Base!L11:L1010,Relatório!C59,Base!H11:H1010) -> 287800 | L59: =I59/I60 -> 0.24420874
C60: Total | F60: =SUM(F56:H59) -> 1000 | I60: =SUM(I56:K59) -> 1178500 | L60: =SUM(L56:N59) -> 1
G68: Nº Incorreto Cartão Aprovado,

Sheet Dashboard

Sheet Tabela Dinamica1
A1: Motivo | B1: Abandono Carrinho | E1: Motivo | F1: Abandono Carrinho | H1: Motivo | I1: Abandono Carrinho
A3: Rótulos de Linha | B3: Soma de Valor_Produto | E3: Rótulos de Linha | F3: Soma de Valor_Produto | H3: Rótulos de Linha | I3: Soma de Valor_Produto
A4: Análise de Dados | B4: 12000 | E4: Ciência de Dados | F4: 12600 | H4: Curso Excel & Power BI | I4: 2400
A5: Total Geral | B5: 12000 | E5: Total Geral | F5: 12600 | H5: Total Geral | I5: 2400
A12: Motivo | B12: Aprovado | E12: Motivo | F12: Aprovado | H12: Motivo | I12: Aprovado
A14: Rótulos de Linha | B14: Soma de Valor_Produto | E14: Rótulos de Linha | F14: Soma de Valor_Produto | H14: Rótulos de Linha | I14: Soma de Valor_Produto
A15: Análise de Dados | B15: 7500 | E15: Ciência de Dados | F15: 19000 | H15: Curso Excel & Power BI | I15: 2400
A16: Total Geral | B16: 7500 | E16: Total Geral | F16: 19000 | H16: Total Geral | I16: 2400
A24: Motivo | B24: Nº Incorreto Cartão | E24: Motivo | F24: Nº Incorreto Cartão | H24: Motivo | I24: Nº Incorreto Cartão
A26: Rótulos de Linha | B26: Soma de Valor_Produto | E26: Rótulos de Linha | F26: Soma de Valor_Produto | H26: Rótulos de Linha | I26: Soma de Valor_Produto
A27: Análise de Dados | B27: 1500 | E27: Ciência de Dados | F27: 15600 | H27: Ciência de Dados | I27: 15600
A28: Total Geral | B28: 1500 | E28: Total Geral | F28: 15600 | H28: Total Geral | I28: 15600
A33: Motivo | B33: Saldo Insuficiente | E33: Motivo | F33: Saldo Insuficiente | H33: Motivo | I33: Saldo Insuficiente
A35: Rótulos de Linha | B35: Soma de Valor_Produto | E35: Rótulos de Linha | F35: Soma de Valor_Produto | H35: Rótulos de Linha | I35: Soma de Valor_Produto
A36: Análise de Dados | B36: 7500 | E36: Ciência de Dados | F36: 19700 | H36: Ciência de Dados | I36: 19700
A37: Total Geral | B37: 7500 | E37: Total Geral | F37: 19700 | H37: Total Geral | I37: 19700

Sheet Tabela_Dinamica2
A1: Motivo | B1: Abandono Carrinho
A3: Soma de Valor_Produto | B3: Rótulos de Coluna
A4: Rótulos de Linha | B4: MAI | C4: Total Geral
A5: Análise de Dados | B5: 12000 | C5: 12000
A6: Total Geral | B6: 12000 | C6: 12000
A22: Vendas aprovadas por mes
A25: Motivo | B25: Aprovado | U25: Mês | V25: MAI
A27: Soma de Valor_Produto | B27: Rótulos de Coluna | Q27: Rótulos de Linha | R27: Soma de Valor_Produto | U27: Rótulos de Linha | V27: Soma de Valor_Produto
A28: Rótulos de Linha | B28: MAI | C28: Total Geral | Q28: Cabinda | R28: 5000 | U28: Venda Perdida | V28: 80900
A29: Análise de Dados | B29: 7500 | C29: 7500 | Q29: Moxico | R29: 5400 | U29: Venda Realizada | V29: 28900
A30: Total Geral | B30: 7500 | C30: 7500 | Q30: Lunda Norte | R30: 5800 | U30: Total Geral | V30: 109800
J31: Segmentação de dados | Q31: Cunene | R31: 6300
Q32: Uíge | R32: 7300
Q33: Icolo e Bengo | R33: 7600
Q34: Cuanza Sul | R34: 7900
Q35: Cuando | R35: 8100
Q36: Bié | R36: 8300
Q37: Luanda | R37: 8400
Q38: Total Geral | R38: 70100
A55: Motivo | B55: Abandono Carrinho
A57: Soma de Valor_Produto | B57: Rótulos de Coluna
A58: Rótulos de Linha | B58: MAI | C58: Total Geral
A59: Análise de Dados | B59: 12000 | C59: 12000
A60: Total Geral | B60: 12000 | C60: 12000
B66: Valor perdido por meses em abandono de carrinhio

Sheet Apoio
A1: ID | B1: Email | C1: Quantidade Vendida | D1: Região | E1: Preço Unitário | F1: Desconto (%) | G1: Lucro | H1: Comissão
A2: 1 | B2: bruno.barbosa1@gmail.com | C2: 6 | D2: Bié | E2: 800 | F2: 10 | G2: 4320
A3: 2 | B3: paulo.pinto2@gmail.com | C3: 2 | D3: Huíla | E3: 1500 | F3: 0 | G3: 3000
A4: 3 | B4: fátima.fernandes3@gmail.com | C4: 13 | D4: Icolo e Bengo | E4: 800 | F4: 10 | G4: 9360
A5: 4 | B5: samuel.monteiro4@gmail.com | C5: 16 | D5: Malanje | E5: 1200 | F5: 10 | G5: 17280
A6: 5 | B6: joaquim.lopes5@gmail.com | C6: 11 | D6: Namibe | E6: 800 | F6: 10 | G6: 7920
A7: 6 | B7: manuel.almeida6@gmail.com | C7: 13 | D7: Lunda Sul | E7: 1200 | F7: 0 | G7: 15600
A8: 7 | B8: samuel.david7@gmail.com | C8: 17 | D8: Moxico Leste | E8: 800 | F8: 15 | G8: 11560
A9: 8 | B9: antónio.gomes8@gmail.com | C9: 5 | D9: Uíge | E9: 800 | F9: 15 | G9: 3400
A10: 9 | B10: antónio.fernandes9@gmail.com | C10: 8 | D10: Moxico | E10: 1500 | F10: 15 | G10: 10200
A11: 10 | B11: benedito.barbosa10@gmail.com | C11: 13 | D11: Icolo e Bengo | E11: 800 | F11: 5 | G11: 9880
A12: 11 | B12: carlos.lukeba11@gmail.com | C12: 13 | D12: Benguela | E12: 800 | F12: 0 | G12: 10400
A13: 12 | B13: david.santos12@gmail.com | C13: 14 | D13: Lunda Sul | E13: 1200 | F13: 0 | G13: 16800
... A1001: 1000 | B1001: samuel.david1000@gmail.com | C1001: 5 | D1001: Uíge | E1001: 1200 | F1001: 15 | G1001: 5100

Sheet Materia
C1: O que será transmido nesta aula
C2: Diferença entre Tabela e Intervalo
C3: editar um intervalo
C4: Soma, Somase, Somases
C5: conta, contavalores , contase, etc..
C6: Procv valor aproximado e extado
C7: Se, E , OU Se composto
C8: Formatação Condicional | D8: Perguntas de Negocios
C9: Tratamento de dados
D10: 1- Qual é o valor vendido por cada provincia?
D11: Qual é o valor vendido por Produto?
D12: Qual é o facturamento total por mês?
D13: Qual é o avalor vendido por cada produto em cada provincia?
D14: Quais são os 3 produtos com maior facturamento
D15: No final saber o total Receita, despesa e Saldo

Sheet Teoria (2)
E1: Funções Pesquisa Kit Revisão Curso Avançado de Excel - Prof. Thiago Terra
E8: Lista Funções Utilizadas
E9: Todas Anteriormente, PROCV, PROCH + Funções Secretas!
E12: Lista Produtos | I12: Pedido Venda
E13: Produto | F13: Preço Unit. | G13: Tipo | I13: Produto | J13: Preço Unit. | K13: Tipo | L13: Peso (gr) | M13: Qt. | N13: Preço Total
E14: Mamão | F14: 2.49 | G14: KG | I14: Bacon | L14: 0.5
E15: Banana Prata | F15: 1.79 | G15: KG | I15: Banana Prata | L15: 3
E16: Pimentão | F16: 1.99 | G16: KG | I16: Maçã | L16: 2
E17: Maçã | F17: 4.99 | G17: KG | I17: Leite | M17: 4
E18: Cenoura | F18: 2.99 | G18: KG | I18: Dúzia Ovos | M18: 3
E19: Batata | F19: 0.98 | G19: KG
E20: Picanha | F20: 40 | G20: KG
E21: Vagem | F21: 3 | G21: KG
E22: Bacon | F22: 15 | G22: KG
E23: Leite | F23: 2.2 | G23: UNIT
E24: Água Mineral | F24: 2 | G24: UNIT
E25: Dúzia Ovos | F25: 5 | G25: UNIT
M29: Total
E34: Base de Clientes | M34: Pesquisa Cliente
E35: Código | F35: Nome | G35: Endereço | H35: Bairro | I35: Cidade | J35: Email | M35: Código
F36: Thiago | G36: Rua A1 | H36: Centro | I36: São Paulo | J36: thiago@nextlevel.run | M36: Nome
F37: Priscila | G37: Rua A2 | H37: Centro | I37: São Paulo | J37: priscila@nextlevel.run | M37: Endereço
F38: Eduardo | G38: Rua A3 | H38: Centro | I38: Belo Horizonte | J38: eduardo@nextlevel.run | M38: Bairro
F39: Camila | G39: Rua A4 | H39: Prado | I39: Belo Horizonte | J39: camila@nextlevel.run | M39: Cidade
F40: João | G40: Rua A5 | H40: Prado | I40: Rio de Janeiro | J40: joao@nextlevel.run | M40: Email
F41: Vicente | G41: Rua A6 | H41: Savassi | I41: Rio de Janeiro | J41: vicente@nextlevel.run
F42: Aline | G42: Rua A7 | H42: Savassi | I42: Belo Horizonte | J42: aline@nextlevel.run
F43: Débora | G43: Rua A8 | H43: Pampulha | I43: Belo Horizonte | J43: debora@nextlevel.run
F44: José | G44: Rua A9 | H44: Pampulha | I44: Rio de Janeiro | J44: jose@nextlevel.run
E49: Base de Vendedores | L49: Vendas Vendedor / Total | O49: Ajuda
E50: Meses | F50: Thiago | G50: Priscila | H50: Eduardo | I50: André | J50: Aline | L50: Total Vendas | O50: Mês 1 | P50: 2
E51: Mês 1 | F51: 32432 | G51: 56356 | H51: 12353 | I51: 32523 | J51: 54675 | L51: Thiago | O51: Mês 2 | P51: 3
E52: Mês 2 | F52: 54675 | G52: 12353 | H52: 12353 | I52: 56356 | J52: 56356 | O52: Mês 3 | P52: 4
E53: Mês 3 | F53: 32523 | G53: 65335 | H53: 54675 | I53: 12353 | J53: 12353 | L53: Vendas Vendedor / Mês | O53: Mês 4 | P53: 5
E54: Mês 4 | F54: 34325 | G54: 32523 | H54: 56356 | I54: 65335 | J54: 65335 | L54: Vendas | O54: Mês 5 | P54: 6
E55: Mês 5 | F55: 3786 | G55: 34325 | H55: 12353 | I55: 32523 | J55: 56356 | L55: Priscila | M55: Mês 2 | O55: Mês 6 | P55: 7
E56: Mês 6 | F56: 56735 | G56: 12353 | H56: 65335 | I56: 34325 | J56: 12353
E57: Total
E62: Calcule a Comissão
E63: Nome | F63: Vendas | G63: Condição | H63: Comissão | J63: Tabela Comissão
...

Sheet Teoria (3)
D1: PROCV e PROCH Prof. Thiago Terra
E9: Lista Produtos | I9: Pedido Venda
E10: Produto | F10: Preço Unit. | G10: Tipo | I10: Produto | J10: Preço Unit. | K10: Tipo | L10: Peso (gr) | M10: Qt. | N10: Preço Total
E11: Mamão | F11: 2.49 | G11: KG | I11: Bacon | L11: 0.5
E12: Banana Prata | F12: 1.79 | G12: KG | I12: Banana Prata | L12: 3
E13: Pimentão | F13: 1.99 | G13: KG | I13: Maçã | L13: 2
E14: Maçã | F14: 4.99 | G14: KG | I14: Leite | M14: 4
E15: Cenoura | F15: 2.99 | G15: KG | I15: Dúzia Ovos | M15: 3
E16: Batata | F16: 0.98 | G16: KG
E17: Picanha | F17: 40 | G17: KG
E18: Vagem | F18: 3 | G18: KG
E19: Bacon | F19: 15 | G19: KG
E20: Leite | F20: 2.2 | G20: UNIT
E21: Água Mineral | F21: 2 | G21: UNIT
E22: Dúzia Ovos | F22: 5 | G22: UNIT
M26: Total
E31: Base de Clientes | M31: Pesquisa Cliente
E32: Código | F32: Nome | G32: Endereço | H32: Bairro | I32: Cidade | J32: Email | M32: Código
F33: Thiago | G33: Rua A1 | H33: Centro | I33: São Paulo | J33: thiago@nextlevel.run | M33: Nome
F34: Priscila | G34: Rua A2 | H34: Centro | I34: São Paulo | J34: priscila@nextlevel.run | M34: Endereço
F35: Eduardo | G35: Rua A3 | H35: Centro | I35: Belo Horizonte | J35: eduardo@nextlevel.run | M35: Bairro
F36: Camila | G36: Rua A4 | H36: Prado | I36: Belo Horizonte | J36: camila@nextlevel.run | M36: Cidade
F37: João | G37: Rua A5 | H37: Prado | I37: Rio de Janeiro | J37: joao@nextlevel.run | M37: Email
F38: Vicente | G38: Rua A6 | H38: Savassi | I38: Rio de Janeiro | J38: vicente@nextlevel.run
F39: Aline | G39: Rua A7 | H39: Savassi | I39: Belo Horizonte | J39: aline@nextlevel.run
F40: Débora | G40: Rua A8 | H40: Pampulha | I40: Belo Horizonte | J40: debora@nextlevel.run
F41: José | G41: Rua A9 | H41: Pampulha | I41: Rio de Janeiro | J41: jose@nextlevel.run
E46: Base de Vendedores | L46: Vendas Vendedor / Total | O46: Ajuda
E47: Meses | F47: Thiago | G47: Priscila | H47: Eduardo | I47: André | J47: Aline | L47: Total Vendas | O47: Mês 1 | P47: 2
E48: Mês 1 | F48: 32432 | G48: 56356 | H48: 12353 | I48: 32523 | J48: 54675 | L48: Thiago | O48: Mês 2 | P48: 3
E49: Mês 2 | F49: 54675 | G49: 12353 | H49: 12353 | I49: 56356 | J49: 56356 | O49: Mês 3 | P49: 4
E50: Mês 3 | F50: 32523 | G50: 65335 | H50: 54675 | I50: 12353 | J50: 12353 | L50: Vendas Vendedor / Mês | O50: Mês 4 | P50: 5
E51: Mês 4 | F51: 34325 | G51: 32523 | H51: 56356 | I51: 65335 | J51: 65335 | L51: Vendas | O51: Mês 5 | P51: 6
E52: Mês 5 | F52: 3786 | G52: 34325 | H52: 12353 | I52: 32523 | J52: 56356 | L52: Priscila | M52: Mês 2 | O52: Mês 6 | P52: 7
E53: Mês 6 | F53: 56735 | G53: 12353 | H53: 65335 | I53: 34325 | J53: 12353
E54: Total
E59: Calcule a Comissão
E60: Nome | F60: Vendas | G60: Condição | H60: Comissão | J60: Tabela Comissão
E61: João | F61: 6000 | G61: PRAZO | J61: 1 | K61: 4999 | L61: 0.01
E62: Eduardo | F62: 17800 | G62: VISTA | J62: 5000 | K62: 9999 | L62: 0.015
...
